{
 "cells": [
  {
   "cell_type": "markdown",
   "metadata": {},
   "source": [
    "# Fetch data with PythonLidar"
   ]
  },
  {
   "cell_type": "markdown",
   "metadata": {},
   "source": [
    "## Imports"
   ]
  },
  {
   "cell_type": "code",
   "execution_count": 19,
   "metadata": {},
   "outputs": [],
   "source": [
    "import os\n",
    "import sys\n",
    "import matplotlib.pyplot as plt\n",
    "from shapely.geometry import Polygon"
   ]
  },
  {
   "cell_type": "code",
   "execution_count": 20,
   "metadata": {},
   "outputs": [],
   "source": [
    "sys.path.append(os.path.abspath(os.path.join('../scripts')))"
   ]
  },
  {
   "cell_type": "code",
   "execution_count": 21,
   "metadata": {},
   "outputs": [
    {
     "name": "stdout",
     "output_type": "stream",
     "text": [
      "2022-06-25 09:25:11,879 — FileHandler — INFO — usgs_3dep_metadata read successfully\n",
      "2022-06-25 09:25:11,879 — FileHandler — INFO — usgs_3dep_metadata read successfully\n",
      "2022-06-25 09:25:11,879 — FileHandler — INFO — usgs_3dep_metadata read successfully\n",
      "2022-06-25 09:25:11,879 — FileHandler — INFO — usgs_3dep_metadata read successfully\n",
      "2022-06-25 09:25:11,879 — FileHandler — INFO — usgs_3dep_metadata read successfully\n",
      "2022-06-25 09:25:11,879 — FileHandler — INFO — usgs_3dep_metadata read successfully\n",
      "2022-06-25 09:25:11,879 — FileHandler — INFO — usgs_3dep_metadata read successfully\n"
     ]
    },
    {
     "name": "stderr",
     "output_type": "stream",
     "text": [
      "--- Logging error ---\n",
      "Traceback (most recent call last):\n",
      "  File \"C:\\Users\\user\\anaconda3\\lib\\logging\\handlers.py\", line 70, in emit\n",
      "    self.doRollover()\n",
      "  File \"C:\\Users\\user\\anaconda3\\lib\\logging\\handlers.py\", line 394, in doRollover\n",
      "    self.rotate(self.baseFilename, dfn)\n",
      "  File \"C:\\Users\\user\\anaconda3\\lib\\logging\\handlers.py\", line 111, in rotate\n",
      "    os.rename(source, dest)\n",
      "PermissionError: [WinError 32] The process cannot access the file because it is being used by another process: 'C:\\\\Users\\\\user\\\\USGS_LIDAR_AgriTech\\\\log\\\\PythonLidara.log' -> 'C:\\\\Users\\\\user\\\\USGS_LIDAR_AgriTech\\\\log\\\\PythonLidara.log.2021-08-24'\n",
      "Call stack:\n",
      "  File \"C:\\Users\\user\\anaconda3\\lib\\runpy.py\", line 194, in _run_module_as_main\n",
      "    return _run_code(code, main_globals, None,\n",
      "  File \"C:\\Users\\user\\anaconda3\\lib\\runpy.py\", line 87, in _run_code\n",
      "    exec(code, run_globals)\n",
      "  File \"C:\\Users\\user\\anaconda3\\lib\\site-packages\\ipykernel_launcher.py\", line 16, in <module>\n",
      "    app.launch_new_instance()\n",
      "  File \"C:\\Users\\user\\anaconda3\\lib\\site-packages\\traitlets\\config\\application.py\", line 846, in launch_instance\n",
      "    app.start()\n",
      "  File \"C:\\Users\\user\\anaconda3\\lib\\site-packages\\ipykernel\\kernelapp.py\", line 677, in start\n",
      "    self.io_loop.start()\n",
      "  File \"C:\\Users\\user\\anaconda3\\lib\\site-packages\\tornado\\platform\\asyncio.py\", line 199, in start\n",
      "    self.asyncio_loop.run_forever()\n",
      "  File \"C:\\Users\\user\\anaconda3\\lib\\asyncio\\base_events.py\", line 570, in run_forever\n",
      "    self._run_once()\n",
      "  File \"C:\\Users\\user\\anaconda3\\lib\\asyncio\\base_events.py\", line 1859, in _run_once\n",
      "    handle._run()\n",
      "  File \"C:\\Users\\user\\anaconda3\\lib\\asyncio\\events.py\", line 81, in _run\n",
      "    self._context.run(self._callback, *self._args)\n",
      "  File \"C:\\Users\\user\\anaconda3\\lib\\site-packages\\ipykernel\\kernelbase.py\", line 471, in dispatch_queue\n",
      "    await self.process_one()\n",
      "  File \"C:\\Users\\user\\anaconda3\\lib\\site-packages\\ipykernel\\kernelbase.py\", line 460, in process_one\n",
      "    await dispatch(*args)\n",
      "  File \"C:\\Users\\user\\anaconda3\\lib\\site-packages\\ipykernel\\kernelbase.py\", line 367, in dispatch_shell\n",
      "    await result\n",
      "  File \"C:\\Users\\user\\anaconda3\\lib\\site-packages\\ipykernel\\kernelbase.py\", line 662, in execute_request\n",
      "    reply_content = await reply_content\n",
      "  File \"C:\\Users\\user\\anaconda3\\lib\\site-packages\\ipykernel\\ipkernel.py\", line 360, in do_execute\n",
      "    res = shell.run_cell(code, store_history=store_history, silent=silent)\n",
      "  File \"C:\\Users\\user\\anaconda3\\lib\\site-packages\\ipykernel\\zmqshell.py\", line 532, in run_cell\n",
      "    return super().run_cell(*args, **kwargs)\n",
      "  File \"C:\\Users\\user\\anaconda3\\lib\\site-packages\\IPython\\core\\interactiveshell.py\", line 2880, in run_cell\n",
      "    result = self._run_cell(\n",
      "  File \"C:\\Users\\user\\anaconda3\\lib\\site-packages\\IPython\\core\\interactiveshell.py\", line 2935, in _run_cell\n",
      "    return runner(coro)\n",
      "  File \"C:\\Users\\user\\anaconda3\\lib\\site-packages\\IPython\\core\\async_helpers.py\", line 129, in _pseudo_sync_runner\n",
      "    coro.send(None)\n",
      "  File \"C:\\Users\\user\\anaconda3\\lib\\site-packages\\IPython\\core\\interactiveshell.py\", line 3134, in run_cell_async\n",
      "    has_raised = await self.run_ast_nodes(code_ast.body, cell_name,\n",
      "  File \"C:\\Users\\user\\anaconda3\\lib\\site-packages\\IPython\\core\\interactiveshell.py\", line 3337, in run_ast_nodes\n",
      "    if await self.run_code(code, result, async_=asy):\n",
      "  File \"C:\\Users\\user\\anaconda3\\lib\\site-packages\\IPython\\core\\interactiveshell.py\", line 3397, in run_code\n",
      "    exec(code_obj, self.user_global_ns, self.user_ns)\n",
      "  File \"C:\\Users\\user\\AppData\\Local\\Temp\\ipykernel_12596\\1274714701.py\", line 2, in <cell line: 2>\n",
      "    pl = PythonLidar(epsg=4326)\n",
      "  File \"C:\\Users\\user\\USGS_LIDAR_AgriTech\\scripts\\python_lidar.py\", line 15, in __init__\n",
      "    self._fetch_lidar = FetchLidar(self.output_epsg)\n",
      "  File \"C:\\Users\\user\\USGS_LIDAR_AgriTech\\scripts\\fetch_lidar.py\", line 28, in __init__\n",
      "    self._metadata = self._file_handler.read_csv(\"usgs_3dep_metadata\")\n",
      "  File \"C:\\Users\\user\\USGS_LIDAR_AgriTech\\scripts\\file_handler.py\", line 44, in read_csv\n",
      "    self._logger.info(f\"{name} read successfully\")\n",
      "Message: 'usgs_3dep_metadata read successfully'\n",
      "Arguments: ()\n",
      "--- Logging error ---\n",
      "Traceback (most recent call last):\n",
      "  File \"C:\\Users\\user\\anaconda3\\lib\\logging\\handlers.py\", line 70, in emit\n",
      "    self.doRollover()\n",
      "  File \"C:\\Users\\user\\anaconda3\\lib\\logging\\handlers.py\", line 394, in doRollover\n",
      "    self.rotate(self.baseFilename, dfn)\n",
      "  File \"C:\\Users\\user\\anaconda3\\lib\\logging\\handlers.py\", line 111, in rotate\n",
      "    os.rename(source, dest)\n",
      "PermissionError: [WinError 32] The process cannot access the file because it is being used by another process: 'C:\\\\Users\\\\user\\\\USGS_LIDAR_AgriTech\\\\log\\\\PythonLidara.log' -> 'C:\\\\Users\\\\user\\\\USGS_LIDAR_AgriTech\\\\log\\\\PythonLidara.log.2021-08-24'\n",
      "Call stack:\n",
      "  File \"C:\\Users\\user\\anaconda3\\lib\\runpy.py\", line 194, in _run_module_as_main\n",
      "    return _run_code(code, main_globals, None,\n",
      "  File \"C:\\Users\\user\\anaconda3\\lib\\runpy.py\", line 87, in _run_code\n",
      "    exec(code, run_globals)\n",
      "  File \"C:\\Users\\user\\anaconda3\\lib\\site-packages\\ipykernel_launcher.py\", line 16, in <module>\n",
      "    app.launch_new_instance()\n",
      "  File \"C:\\Users\\user\\anaconda3\\lib\\site-packages\\traitlets\\config\\application.py\", line 846, in launch_instance\n",
      "    app.start()\n",
      "  File \"C:\\Users\\user\\anaconda3\\lib\\site-packages\\ipykernel\\kernelapp.py\", line 677, in start\n",
      "    self.io_loop.start()\n",
      "  File \"C:\\Users\\user\\anaconda3\\lib\\site-packages\\tornado\\platform\\asyncio.py\", line 199, in start\n",
      "    self.asyncio_loop.run_forever()\n",
      "  File \"C:\\Users\\user\\anaconda3\\lib\\asyncio\\base_events.py\", line 570, in run_forever\n",
      "    self._run_once()\n",
      "  File \"C:\\Users\\user\\anaconda3\\lib\\asyncio\\base_events.py\", line 1859, in _run_once\n",
      "    handle._run()\n",
      "  File \"C:\\Users\\user\\anaconda3\\lib\\asyncio\\events.py\", line 81, in _run\n",
      "    self._context.run(self._callback, *self._args)\n",
      "  File \"C:\\Users\\user\\anaconda3\\lib\\site-packages\\ipykernel\\kernelbase.py\", line 471, in dispatch_queue\n",
      "    await self.process_one()\n",
      "  File \"C:\\Users\\user\\anaconda3\\lib\\site-packages\\ipykernel\\kernelbase.py\", line 460, in process_one\n",
      "    await dispatch(*args)\n",
      "  File \"C:\\Users\\user\\anaconda3\\lib\\site-packages\\ipykernel\\kernelbase.py\", line 367, in dispatch_shell\n",
      "    await result\n",
      "  File \"C:\\Users\\user\\anaconda3\\lib\\site-packages\\ipykernel\\kernelbase.py\", line 662, in execute_request\n",
      "    reply_content = await reply_content\n",
      "  File \"C:\\Users\\user\\anaconda3\\lib\\site-packages\\ipykernel\\ipkernel.py\", line 360, in do_execute\n",
      "    res = shell.run_cell(code, store_history=store_history, silent=silent)\n",
      "  File \"C:\\Users\\user\\anaconda3\\lib\\site-packages\\ipykernel\\zmqshell.py\", line 532, in run_cell\n",
      "    return super().run_cell(*args, **kwargs)\n",
      "  File \"C:\\Users\\user\\anaconda3\\lib\\site-packages\\IPython\\core\\interactiveshell.py\", line 2880, in run_cell\n",
      "    result = self._run_cell(\n",
      "  File \"C:\\Users\\user\\anaconda3\\lib\\site-packages\\IPython\\core\\interactiveshell.py\", line 2935, in _run_cell\n",
      "    return runner(coro)\n",
      "  File \"C:\\Users\\user\\anaconda3\\lib\\site-packages\\IPython\\core\\async_helpers.py\", line 129, in _pseudo_sync_runner\n",
      "    coro.send(None)\n",
      "  File \"C:\\Users\\user\\anaconda3\\lib\\site-packages\\IPython\\core\\interactiveshell.py\", line 3134, in run_cell_async\n",
      "    has_raised = await self.run_ast_nodes(code_ast.body, cell_name,\n",
      "  File \"C:\\Users\\user\\anaconda3\\lib\\site-packages\\IPython\\core\\interactiveshell.py\", line 3337, in run_ast_nodes\n",
      "    if await self.run_code(code, result, async_=asy):\n",
      "  File \"C:\\Users\\user\\anaconda3\\lib\\site-packages\\IPython\\core\\interactiveshell.py\", line 3397, in run_code\n",
      "    exec(code_obj, self.user_global_ns, self.user_ns)\n",
      "  File \"C:\\Users\\user\\AppData\\Local\\Temp\\ipykernel_12596\\1274714701.py\", line 2, in <cell line: 2>\n",
      "    pl = PythonLidar(epsg=4326)\n",
      "  File \"C:\\Users\\user\\USGS_LIDAR_AgriTech\\scripts\\python_lidar.py\", line 15, in __init__\n",
      "    self._fetch_lidar = FetchLidar(self.output_epsg)\n",
      "  File \"C:\\Users\\user\\USGS_LIDAR_AgriTech\\scripts\\fetch_lidar.py\", line 28, in __init__\n",
      "    self._metadata = self._file_handler.read_csv(\"usgs_3dep_metadata\")\n",
      "  File \"C:\\Users\\user\\USGS_LIDAR_AgriTech\\scripts\\file_handler.py\", line 44, in read_csv\n",
      "    self._logger.info(f\"{name} read successfully\")\n",
      "Message: 'usgs_3dep_metadata read successfully'\n",
      "Arguments: ()\n",
      "--- Logging error ---\n",
      "Traceback (most recent call last):\n",
      "  File \"C:\\Users\\user\\anaconda3\\lib\\logging\\handlers.py\", line 70, in emit\n",
      "    self.doRollover()\n",
      "  File \"C:\\Users\\user\\anaconda3\\lib\\logging\\handlers.py\", line 394, in doRollover\n",
      "    self.rotate(self.baseFilename, dfn)\n",
      "  File \"C:\\Users\\user\\anaconda3\\lib\\logging\\handlers.py\", line 111, in rotate\n",
      "    os.rename(source, dest)\n",
      "PermissionError: [WinError 32] The process cannot access the file because it is being used by another process: 'C:\\\\Users\\\\user\\\\USGS_LIDAR_AgriTech\\\\log\\\\PythonLidara.log' -> 'C:\\\\Users\\\\user\\\\USGS_LIDAR_AgriTech\\\\log\\\\PythonLidara.log.2021-08-24'\n",
      "Call stack:\n",
      "  File \"C:\\Users\\user\\anaconda3\\lib\\runpy.py\", line 194, in _run_module_as_main\n",
      "    return _run_code(code, main_globals, None,\n",
      "  File \"C:\\Users\\user\\anaconda3\\lib\\runpy.py\", line 87, in _run_code\n",
      "    exec(code, run_globals)\n",
      "  File \"C:\\Users\\user\\anaconda3\\lib\\site-packages\\ipykernel_launcher.py\", line 16, in <module>\n",
      "    app.launch_new_instance()\n",
      "  File \"C:\\Users\\user\\anaconda3\\lib\\site-packages\\traitlets\\config\\application.py\", line 846, in launch_instance\n",
      "    app.start()\n",
      "  File \"C:\\Users\\user\\anaconda3\\lib\\site-packages\\ipykernel\\kernelapp.py\", line 677, in start\n",
      "    self.io_loop.start()\n",
      "  File \"C:\\Users\\user\\anaconda3\\lib\\site-packages\\tornado\\platform\\asyncio.py\", line 199, in start\n",
      "    self.asyncio_loop.run_forever()\n",
      "  File \"C:\\Users\\user\\anaconda3\\lib\\asyncio\\base_events.py\", line 570, in run_forever\n",
      "    self._run_once()\n",
      "  File \"C:\\Users\\user\\anaconda3\\lib\\asyncio\\base_events.py\", line 1859, in _run_once\n",
      "    handle._run()\n",
      "  File \"C:\\Users\\user\\anaconda3\\lib\\asyncio\\events.py\", line 81, in _run\n",
      "    self._context.run(self._callback, *self._args)\n",
      "  File \"C:\\Users\\user\\anaconda3\\lib\\site-packages\\ipykernel\\kernelbase.py\", line 471, in dispatch_queue\n",
      "    await self.process_one()\n",
      "  File \"C:\\Users\\user\\anaconda3\\lib\\site-packages\\ipykernel\\kernelbase.py\", line 460, in process_one\n",
      "    await dispatch(*args)\n",
      "  File \"C:\\Users\\user\\anaconda3\\lib\\site-packages\\ipykernel\\kernelbase.py\", line 367, in dispatch_shell\n",
      "    await result\n",
      "  File \"C:\\Users\\user\\anaconda3\\lib\\site-packages\\ipykernel\\kernelbase.py\", line 662, in execute_request\n",
      "    reply_content = await reply_content\n",
      "  File \"C:\\Users\\user\\anaconda3\\lib\\site-packages\\ipykernel\\ipkernel.py\", line 360, in do_execute\n",
      "    res = shell.run_cell(code, store_history=store_history, silent=silent)\n",
      "  File \"C:\\Users\\user\\anaconda3\\lib\\site-packages\\ipykernel\\zmqshell.py\", line 532, in run_cell\n",
      "    return super().run_cell(*args, **kwargs)\n",
      "  File \"C:\\Users\\user\\anaconda3\\lib\\site-packages\\IPython\\core\\interactiveshell.py\", line 2880, in run_cell\n",
      "    result = self._run_cell(\n",
      "  File \"C:\\Users\\user\\anaconda3\\lib\\site-packages\\IPython\\core\\interactiveshell.py\", line 2935, in _run_cell\n",
      "    return runner(coro)\n",
      "  File \"C:\\Users\\user\\anaconda3\\lib\\site-packages\\IPython\\core\\async_helpers.py\", line 129, in _pseudo_sync_runner\n",
      "    coro.send(None)\n",
      "  File \"C:\\Users\\user\\anaconda3\\lib\\site-packages\\IPython\\core\\interactiveshell.py\", line 3134, in run_cell_async\n",
      "    has_raised = await self.run_ast_nodes(code_ast.body, cell_name,\n",
      "  File \"C:\\Users\\user\\anaconda3\\lib\\site-packages\\IPython\\core\\interactiveshell.py\", line 3337, in run_ast_nodes\n",
      "    if await self.run_code(code, result, async_=asy):\n",
      "  File \"C:\\Users\\user\\anaconda3\\lib\\site-packages\\IPython\\core\\interactiveshell.py\", line 3397, in run_code\n",
      "    exec(code_obj, self.user_global_ns, self.user_ns)\n",
      "  File \"C:\\Users\\user\\AppData\\Local\\Temp\\ipykernel_12596\\1274714701.py\", line 2, in <cell line: 2>\n",
      "    pl = PythonLidar(epsg=4326)\n",
      "  File \"C:\\Users\\user\\USGS_LIDAR_AgriTech\\scripts\\python_lidar.py\", line 15, in __init__\n",
      "    self._fetch_lidar = FetchLidar(self.output_epsg)\n",
      "  File \"C:\\Users\\user\\USGS_LIDAR_AgriTech\\scripts\\fetch_lidar.py\", line 28, in __init__\n",
      "    self._metadata = self._file_handler.read_csv(\"usgs_3dep_metadata\")\n",
      "  File \"C:\\Users\\user\\USGS_LIDAR_AgriTech\\scripts\\file_handler.py\", line 44, in read_csv\n",
      "    self._logger.info(f\"{name} read successfully\")\n",
      "Message: 'usgs_3dep_metadata read successfully'\n",
      "Arguments: ()\n",
      "--- Logging error ---\n",
      "Traceback (most recent call last):\n",
      "  File \"C:\\Users\\user\\anaconda3\\lib\\logging\\handlers.py\", line 70, in emit\n",
      "    self.doRollover()\n",
      "  File \"C:\\Users\\user\\anaconda3\\lib\\logging\\handlers.py\", line 394, in doRollover\n",
      "    self.rotate(self.baseFilename, dfn)\n",
      "  File \"C:\\Users\\user\\anaconda3\\lib\\logging\\handlers.py\", line 111, in rotate\n",
      "    os.rename(source, dest)\n",
      "PermissionError: [WinError 32] The process cannot access the file because it is being used by another process: 'C:\\\\Users\\\\user\\\\USGS_LIDAR_AgriTech\\\\log\\\\PythonLidara.log' -> 'C:\\\\Users\\\\user\\\\USGS_LIDAR_AgriTech\\\\log\\\\PythonLidara.log.2021-08-24'\n",
      "Call stack:\n",
      "  File \"C:\\Users\\user\\anaconda3\\lib\\runpy.py\", line 194, in _run_module_as_main\n",
      "    return _run_code(code, main_globals, None,\n",
      "  File \"C:\\Users\\user\\anaconda3\\lib\\runpy.py\", line 87, in _run_code\n",
      "    exec(code, run_globals)\n",
      "  File \"C:\\Users\\user\\anaconda3\\lib\\site-packages\\ipykernel_launcher.py\", line 16, in <module>\n",
      "    app.launch_new_instance()\n",
      "  File \"C:\\Users\\user\\anaconda3\\lib\\site-packages\\traitlets\\config\\application.py\", line 846, in launch_instance\n",
      "    app.start()\n",
      "  File \"C:\\Users\\user\\anaconda3\\lib\\site-packages\\ipykernel\\kernelapp.py\", line 677, in start\n",
      "    self.io_loop.start()\n",
      "  File \"C:\\Users\\user\\anaconda3\\lib\\site-packages\\tornado\\platform\\asyncio.py\", line 199, in start\n",
      "    self.asyncio_loop.run_forever()\n",
      "  File \"C:\\Users\\user\\anaconda3\\lib\\asyncio\\base_events.py\", line 570, in run_forever\n",
      "    self._run_once()\n",
      "  File \"C:\\Users\\user\\anaconda3\\lib\\asyncio\\base_events.py\", line 1859, in _run_once\n",
      "    handle._run()\n",
      "  File \"C:\\Users\\user\\anaconda3\\lib\\asyncio\\events.py\", line 81, in _run\n",
      "    self._context.run(self._callback, *self._args)\n",
      "  File \"C:\\Users\\user\\anaconda3\\lib\\site-packages\\ipykernel\\kernelbase.py\", line 471, in dispatch_queue\n",
      "    await self.process_one()\n",
      "  File \"C:\\Users\\user\\anaconda3\\lib\\site-packages\\ipykernel\\kernelbase.py\", line 460, in process_one\n",
      "    await dispatch(*args)\n",
      "  File \"C:\\Users\\user\\anaconda3\\lib\\site-packages\\ipykernel\\kernelbase.py\", line 367, in dispatch_shell\n",
      "    await result\n",
      "  File \"C:\\Users\\user\\anaconda3\\lib\\site-packages\\ipykernel\\kernelbase.py\", line 662, in execute_request\n",
      "    reply_content = await reply_content\n",
      "  File \"C:\\Users\\user\\anaconda3\\lib\\site-packages\\ipykernel\\ipkernel.py\", line 360, in do_execute\n",
      "    res = shell.run_cell(code, store_history=store_history, silent=silent)\n",
      "  File \"C:\\Users\\user\\anaconda3\\lib\\site-packages\\ipykernel\\zmqshell.py\", line 532, in run_cell\n",
      "    return super().run_cell(*args, **kwargs)\n",
      "  File \"C:\\Users\\user\\anaconda3\\lib\\site-packages\\IPython\\core\\interactiveshell.py\", line 2880, in run_cell\n",
      "    result = self._run_cell(\n",
      "  File \"C:\\Users\\user\\anaconda3\\lib\\site-packages\\IPython\\core\\interactiveshell.py\", line 2935, in _run_cell\n",
      "    return runner(coro)\n",
      "  File \"C:\\Users\\user\\anaconda3\\lib\\site-packages\\IPython\\core\\async_helpers.py\", line 129, in _pseudo_sync_runner\n",
      "    coro.send(None)\n",
      "  File \"C:\\Users\\user\\anaconda3\\lib\\site-packages\\IPython\\core\\interactiveshell.py\", line 3134, in run_cell_async\n",
      "    has_raised = await self.run_ast_nodes(code_ast.body, cell_name,\n",
      "  File \"C:\\Users\\user\\anaconda3\\lib\\site-packages\\IPython\\core\\interactiveshell.py\", line 3337, in run_ast_nodes\n",
      "    if await self.run_code(code, result, async_=asy):\n",
      "  File \"C:\\Users\\user\\anaconda3\\lib\\site-packages\\IPython\\core\\interactiveshell.py\", line 3397, in run_code\n",
      "    exec(code_obj, self.user_global_ns, self.user_ns)\n",
      "  File \"C:\\Users\\user\\AppData\\Local\\Temp\\ipykernel_12596\\1274714701.py\", line 2, in <cell line: 2>\n",
      "    pl = PythonLidar(epsg=4326)\n",
      "  File \"C:\\Users\\user\\USGS_LIDAR_AgriTech\\scripts\\python_lidar.py\", line 15, in __init__\n",
      "    self._fetch_lidar = FetchLidar(self.output_epsg)\n",
      "  File \"C:\\Users\\user\\USGS_LIDAR_AgriTech\\scripts\\fetch_lidar.py\", line 28, in __init__\n",
      "    self._metadata = self._file_handler.read_csv(\"usgs_3dep_metadata\")\n",
      "  File \"C:\\Users\\user\\USGS_LIDAR_AgriTech\\scripts\\file_handler.py\", line 44, in read_csv\n",
      "    self._logger.info(f\"{name} read successfully\")\n",
      "Message: 'usgs_3dep_metadata read successfully'\n",
      "Arguments: ()\n",
      "--- Logging error ---\n",
      "Traceback (most recent call last):\n",
      "  File \"C:\\Users\\user\\anaconda3\\lib\\logging\\handlers.py\", line 70, in emit\n",
      "    self.doRollover()\n",
      "  File \"C:\\Users\\user\\anaconda3\\lib\\logging\\handlers.py\", line 394, in doRollover\n",
      "    self.rotate(self.baseFilename, dfn)\n",
      "  File \"C:\\Users\\user\\anaconda3\\lib\\logging\\handlers.py\", line 111, in rotate\n",
      "    os.rename(source, dest)\n",
      "PermissionError: [WinError 32] The process cannot access the file because it is being used by another process: 'C:\\\\Users\\\\user\\\\USGS_LIDAR_AgriTech\\\\log\\\\PythonLidara.log' -> 'C:\\\\Users\\\\user\\\\USGS_LIDAR_AgriTech\\\\log\\\\PythonLidara.log.2021-08-24'\n",
      "Call stack:\n",
      "  File \"C:\\Users\\user\\anaconda3\\lib\\runpy.py\", line 194, in _run_module_as_main\n",
      "    return _run_code(code, main_globals, None,\n",
      "  File \"C:\\Users\\user\\anaconda3\\lib\\runpy.py\", line 87, in _run_code\n",
      "    exec(code, run_globals)\n",
      "  File \"C:\\Users\\user\\anaconda3\\lib\\site-packages\\ipykernel_launcher.py\", line 16, in <module>\n",
      "    app.launch_new_instance()\n",
      "  File \"C:\\Users\\user\\anaconda3\\lib\\site-packages\\traitlets\\config\\application.py\", line 846, in launch_instance\n",
      "    app.start()\n",
      "  File \"C:\\Users\\user\\anaconda3\\lib\\site-packages\\ipykernel\\kernelapp.py\", line 677, in start\n",
      "    self.io_loop.start()\n",
      "  File \"C:\\Users\\user\\anaconda3\\lib\\site-packages\\tornado\\platform\\asyncio.py\", line 199, in start\n",
      "    self.asyncio_loop.run_forever()\n",
      "  File \"C:\\Users\\user\\anaconda3\\lib\\asyncio\\base_events.py\", line 570, in run_forever\n",
      "    self._run_once()\n",
      "  File \"C:\\Users\\user\\anaconda3\\lib\\asyncio\\base_events.py\", line 1859, in _run_once\n",
      "    handle._run()\n",
      "  File \"C:\\Users\\user\\anaconda3\\lib\\asyncio\\events.py\", line 81, in _run\n",
      "    self._context.run(self._callback, *self._args)\n",
      "  File \"C:\\Users\\user\\anaconda3\\lib\\site-packages\\ipykernel\\kernelbase.py\", line 471, in dispatch_queue\n",
      "    await self.process_one()\n",
      "  File \"C:\\Users\\user\\anaconda3\\lib\\site-packages\\ipykernel\\kernelbase.py\", line 460, in process_one\n",
      "    await dispatch(*args)\n",
      "  File \"C:\\Users\\user\\anaconda3\\lib\\site-packages\\ipykernel\\kernelbase.py\", line 367, in dispatch_shell\n",
      "    await result\n",
      "  File \"C:\\Users\\user\\anaconda3\\lib\\site-packages\\ipykernel\\kernelbase.py\", line 662, in execute_request\n",
      "    reply_content = await reply_content\n",
      "  File \"C:\\Users\\user\\anaconda3\\lib\\site-packages\\ipykernel\\ipkernel.py\", line 360, in do_execute\n",
      "    res = shell.run_cell(code, store_history=store_history, silent=silent)\n",
      "  File \"C:\\Users\\user\\anaconda3\\lib\\site-packages\\ipykernel\\zmqshell.py\", line 532, in run_cell\n",
      "    return super().run_cell(*args, **kwargs)\n",
      "  File \"C:\\Users\\user\\anaconda3\\lib\\site-packages\\IPython\\core\\interactiveshell.py\", line 2880, in run_cell\n",
      "    result = self._run_cell(\n",
      "  File \"C:\\Users\\user\\anaconda3\\lib\\site-packages\\IPython\\core\\interactiveshell.py\", line 2935, in _run_cell\n",
      "    return runner(coro)\n",
      "  File \"C:\\Users\\user\\anaconda3\\lib\\site-packages\\IPython\\core\\async_helpers.py\", line 129, in _pseudo_sync_runner\n",
      "    coro.send(None)\n",
      "  File \"C:\\Users\\user\\anaconda3\\lib\\site-packages\\IPython\\core\\interactiveshell.py\", line 3134, in run_cell_async\n",
      "    has_raised = await self.run_ast_nodes(code_ast.body, cell_name,\n",
      "  File \"C:\\Users\\user\\anaconda3\\lib\\site-packages\\IPython\\core\\interactiveshell.py\", line 3337, in run_ast_nodes\n",
      "    if await self.run_code(code, result, async_=asy):\n",
      "  File \"C:\\Users\\user\\anaconda3\\lib\\site-packages\\IPython\\core\\interactiveshell.py\", line 3397, in run_code\n",
      "    exec(code_obj, self.user_global_ns, self.user_ns)\n",
      "  File \"C:\\Users\\user\\AppData\\Local\\Temp\\ipykernel_12596\\1274714701.py\", line 2, in <cell line: 2>\n",
      "    pl = PythonLidar(epsg=4326)\n",
      "  File \"C:\\Users\\user\\USGS_LIDAR_AgriTech\\scripts\\python_lidar.py\", line 15, in __init__\n",
      "    self._fetch_lidar = FetchLidar(self.output_epsg)\n",
      "  File \"C:\\Users\\user\\USGS_LIDAR_AgriTech\\scripts\\fetch_lidar.py\", line 28, in __init__\n",
      "    self._metadata = self._file_handler.read_csv(\"usgs_3dep_metadata\")\n",
      "  File \"C:\\Users\\user\\USGS_LIDAR_AgriTech\\scripts\\file_handler.py\", line 44, in read_csv\n",
      "    self._logger.info(f\"{name} read successfully\")\n",
      "Message: 'usgs_3dep_metadata read successfully'\n",
      "Arguments: ()\n",
      "--- Logging error ---\n",
      "Traceback (most recent call last):\n",
      "  File \"C:\\Users\\user\\anaconda3\\lib\\logging\\handlers.py\", line 70, in emit\n",
      "    self.doRollover()\n",
      "  File \"C:\\Users\\user\\anaconda3\\lib\\logging\\handlers.py\", line 394, in doRollover\n",
      "    self.rotate(self.baseFilename, dfn)\n",
      "  File \"C:\\Users\\user\\anaconda3\\lib\\logging\\handlers.py\", line 111, in rotate\n",
      "    os.rename(source, dest)\n",
      "PermissionError: [WinError 32] The process cannot access the file because it is being used by another process: 'C:\\\\Users\\\\user\\\\USGS_LIDAR_AgriTech\\\\log\\\\PythonLidara.log' -> 'C:\\\\Users\\\\user\\\\USGS_LIDAR_AgriTech\\\\log\\\\PythonLidara.log.2021-08-24'\n",
      "Call stack:\n",
      "  File \"C:\\Users\\user\\anaconda3\\lib\\runpy.py\", line 194, in _run_module_as_main\n",
      "    return _run_code(code, main_globals, None,\n",
      "  File \"C:\\Users\\user\\anaconda3\\lib\\runpy.py\", line 87, in _run_code\n",
      "    exec(code, run_globals)\n",
      "  File \"C:\\Users\\user\\anaconda3\\lib\\site-packages\\ipykernel_launcher.py\", line 16, in <module>\n",
      "    app.launch_new_instance()\n",
      "  File \"C:\\Users\\user\\anaconda3\\lib\\site-packages\\traitlets\\config\\application.py\", line 846, in launch_instance\n",
      "    app.start()\n",
      "  File \"C:\\Users\\user\\anaconda3\\lib\\site-packages\\ipykernel\\kernelapp.py\", line 677, in start\n",
      "    self.io_loop.start()\n",
      "  File \"C:\\Users\\user\\anaconda3\\lib\\site-packages\\tornado\\platform\\asyncio.py\", line 199, in start\n",
      "    self.asyncio_loop.run_forever()\n",
      "  File \"C:\\Users\\user\\anaconda3\\lib\\asyncio\\base_events.py\", line 570, in run_forever\n",
      "    self._run_once()\n",
      "  File \"C:\\Users\\user\\anaconda3\\lib\\asyncio\\base_events.py\", line 1859, in _run_once\n",
      "    handle._run()\n",
      "  File \"C:\\Users\\user\\anaconda3\\lib\\asyncio\\events.py\", line 81, in _run\n",
      "    self._context.run(self._callback, *self._args)\n",
      "  File \"C:\\Users\\user\\anaconda3\\lib\\site-packages\\ipykernel\\kernelbase.py\", line 471, in dispatch_queue\n",
      "    await self.process_one()\n",
      "  File \"C:\\Users\\user\\anaconda3\\lib\\site-packages\\ipykernel\\kernelbase.py\", line 460, in process_one\n",
      "    await dispatch(*args)\n",
      "  File \"C:\\Users\\user\\anaconda3\\lib\\site-packages\\ipykernel\\kernelbase.py\", line 367, in dispatch_shell\n",
      "    await result\n",
      "  File \"C:\\Users\\user\\anaconda3\\lib\\site-packages\\ipykernel\\kernelbase.py\", line 662, in execute_request\n",
      "    reply_content = await reply_content\n",
      "  File \"C:\\Users\\user\\anaconda3\\lib\\site-packages\\ipykernel\\ipkernel.py\", line 360, in do_execute\n",
      "    res = shell.run_cell(code, store_history=store_history, silent=silent)\n",
      "  File \"C:\\Users\\user\\anaconda3\\lib\\site-packages\\ipykernel\\zmqshell.py\", line 532, in run_cell\n",
      "    return super().run_cell(*args, **kwargs)\n",
      "  File \"C:\\Users\\user\\anaconda3\\lib\\site-packages\\IPython\\core\\interactiveshell.py\", line 2880, in run_cell\n",
      "    result = self._run_cell(\n",
      "  File \"C:\\Users\\user\\anaconda3\\lib\\site-packages\\IPython\\core\\interactiveshell.py\", line 2935, in _run_cell\n",
      "    return runner(coro)\n",
      "  File \"C:\\Users\\user\\anaconda3\\lib\\site-packages\\IPython\\core\\async_helpers.py\", line 129, in _pseudo_sync_runner\n",
      "    coro.send(None)\n",
      "  File \"C:\\Users\\user\\anaconda3\\lib\\site-packages\\IPython\\core\\interactiveshell.py\", line 3134, in run_cell_async\n",
      "    has_raised = await self.run_ast_nodes(code_ast.body, cell_name,\n",
      "  File \"C:\\Users\\user\\anaconda3\\lib\\site-packages\\IPython\\core\\interactiveshell.py\", line 3337, in run_ast_nodes\n",
      "    if await self.run_code(code, result, async_=asy):\n",
      "  File \"C:\\Users\\user\\anaconda3\\lib\\site-packages\\IPython\\core\\interactiveshell.py\", line 3397, in run_code\n",
      "    exec(code_obj, self.user_global_ns, self.user_ns)\n",
      "  File \"C:\\Users\\user\\AppData\\Local\\Temp\\ipykernel_12596\\1274714701.py\", line 2, in <cell line: 2>\n",
      "    pl = PythonLidar(epsg=4326)\n",
      "  File \"C:\\Users\\user\\USGS_LIDAR_AgriTech\\scripts\\python_lidar.py\", line 15, in __init__\n",
      "    self._fetch_lidar = FetchLidar(self.output_epsg)\n",
      "  File \"C:\\Users\\user\\USGS_LIDAR_AgriTech\\scripts\\fetch_lidar.py\", line 28, in __init__\n",
      "    self._metadata = self._file_handler.read_csv(\"usgs_3dep_metadata\")\n",
      "  File \"C:\\Users\\user\\USGS_LIDAR_AgriTech\\scripts\\file_handler.py\", line 44, in read_csv\n",
      "    self._logger.info(f\"{name} read successfully\")\n",
      "Message: 'usgs_3dep_metadata read successfully'\n",
      "Arguments: ()\n",
      "--- Logging error ---\n",
      "Traceback (most recent call last):\n",
      "  File \"C:\\Users\\user\\anaconda3\\lib\\logging\\handlers.py\", line 70, in emit\n",
      "    self.doRollover()\n",
      "  File \"C:\\Users\\user\\anaconda3\\lib\\logging\\handlers.py\", line 394, in doRollover\n",
      "    self.rotate(self.baseFilename, dfn)\n",
      "  File \"C:\\Users\\user\\anaconda3\\lib\\logging\\handlers.py\", line 111, in rotate\n",
      "    os.rename(source, dest)\n",
      "PermissionError: [WinError 32] The process cannot access the file because it is being used by another process: 'C:\\\\Users\\\\user\\\\USGS_LIDAR_AgriTech\\\\log\\\\PythonLidara.log' -> 'C:\\\\Users\\\\user\\\\USGS_LIDAR_AgriTech\\\\log\\\\PythonLidara.log.2021-08-24'\n",
      "Call stack:\n",
      "  File \"C:\\Users\\user\\anaconda3\\lib\\runpy.py\", line 194, in _run_module_as_main\n",
      "    return _run_code(code, main_globals, None,\n",
      "  File \"C:\\Users\\user\\anaconda3\\lib\\runpy.py\", line 87, in _run_code\n",
      "    exec(code, run_globals)\n",
      "  File \"C:\\Users\\user\\anaconda3\\lib\\site-packages\\ipykernel_launcher.py\", line 16, in <module>\n",
      "    app.launch_new_instance()\n",
      "  File \"C:\\Users\\user\\anaconda3\\lib\\site-packages\\traitlets\\config\\application.py\", line 846, in launch_instance\n",
      "    app.start()\n",
      "  File \"C:\\Users\\user\\anaconda3\\lib\\site-packages\\ipykernel\\kernelapp.py\", line 677, in start\n",
      "    self.io_loop.start()\n",
      "  File \"C:\\Users\\user\\anaconda3\\lib\\site-packages\\tornado\\platform\\asyncio.py\", line 199, in start\n",
      "    self.asyncio_loop.run_forever()\n",
      "  File \"C:\\Users\\user\\anaconda3\\lib\\asyncio\\base_events.py\", line 570, in run_forever\n",
      "    self._run_once()\n",
      "  File \"C:\\Users\\user\\anaconda3\\lib\\asyncio\\base_events.py\", line 1859, in _run_once\n",
      "    handle._run()\n",
      "  File \"C:\\Users\\user\\anaconda3\\lib\\asyncio\\events.py\", line 81, in _run\n",
      "    self._context.run(self._callback, *self._args)\n",
      "  File \"C:\\Users\\user\\anaconda3\\lib\\site-packages\\ipykernel\\kernelbase.py\", line 471, in dispatch_queue\n",
      "    await self.process_one()\n",
      "  File \"C:\\Users\\user\\anaconda3\\lib\\site-packages\\ipykernel\\kernelbase.py\", line 460, in process_one\n",
      "    await dispatch(*args)\n",
      "  File \"C:\\Users\\user\\anaconda3\\lib\\site-packages\\ipykernel\\kernelbase.py\", line 367, in dispatch_shell\n",
      "    await result\n",
      "  File \"C:\\Users\\user\\anaconda3\\lib\\site-packages\\ipykernel\\kernelbase.py\", line 662, in execute_request\n",
      "    reply_content = await reply_content\n",
      "  File \"C:\\Users\\user\\anaconda3\\lib\\site-packages\\ipykernel\\ipkernel.py\", line 360, in do_execute\n",
      "    res = shell.run_cell(code, store_history=store_history, silent=silent)\n",
      "  File \"C:\\Users\\user\\anaconda3\\lib\\site-packages\\ipykernel\\zmqshell.py\", line 532, in run_cell\n",
      "    return super().run_cell(*args, **kwargs)\n",
      "  File \"C:\\Users\\user\\anaconda3\\lib\\site-packages\\IPython\\core\\interactiveshell.py\", line 2880, in run_cell\n",
      "    result = self._run_cell(\n",
      "  File \"C:\\Users\\user\\anaconda3\\lib\\site-packages\\IPython\\core\\interactiveshell.py\", line 2935, in _run_cell\n",
      "    return runner(coro)\n",
      "  File \"C:\\Users\\user\\anaconda3\\lib\\site-packages\\IPython\\core\\async_helpers.py\", line 129, in _pseudo_sync_runner\n",
      "    coro.send(None)\n",
      "  File \"C:\\Users\\user\\anaconda3\\lib\\site-packages\\IPython\\core\\interactiveshell.py\", line 3134, in run_cell_async\n",
      "    has_raised = await self.run_ast_nodes(code_ast.body, cell_name,\n",
      "  File \"C:\\Users\\user\\anaconda3\\lib\\site-packages\\IPython\\core\\interactiveshell.py\", line 3337, in run_ast_nodes\n",
      "    if await self.run_code(code, result, async_=asy):\n",
      "  File \"C:\\Users\\user\\anaconda3\\lib\\site-packages\\IPython\\core\\interactiveshell.py\", line 3397, in run_code\n",
      "    exec(code_obj, self.user_global_ns, self.user_ns)\n",
      "  File \"C:\\Users\\user\\AppData\\Local\\Temp\\ipykernel_12596\\1274714701.py\", line 2, in <cell line: 2>\n",
      "    pl = PythonLidar(epsg=4326)\n",
      "  File \"C:\\Users\\user\\USGS_LIDAR_AgriTech\\scripts\\python_lidar.py\", line 15, in __init__\n",
      "    self._fetch_lidar = FetchLidar(self.output_epsg)\n",
      "  File \"C:\\Users\\user\\USGS_LIDAR_AgriTech\\scripts\\fetch_lidar.py\", line 28, in __init__\n",
      "    self._metadata = self._file_handler.read_csv(\"usgs_3dep_metadata\")\n",
      "  File \"C:\\Users\\user\\USGS_LIDAR_AgriTech\\scripts\\file_handler.py\", line 44, in read_csv\n",
      "    self._logger.info(f\"{name} read successfully\")\n",
      "Message: 'usgs_3dep_metadata read successfully'\n",
      "Arguments: ()\n"
     ]
    }
   ],
   "source": [
    "from python_lidar import PythonLidar\n",
    "pl = PythonLidar(epsg=4326)"
   ]
  },
  {
   "cell_type": "markdown",
   "metadata": {},
   "source": [
    "## Fetch USGS 3DEP Lidar data"
   ]
  },
  {
   "cell_type": "code",
   "execution_count": 22,
   "metadata": {},
   "outputs": [
    {
     "data": {
      "image/svg+xml": [
       "<svg xmlns=\"http://www.w3.org/2000/svg\" xmlns:xlink=\"http://www.w3.org/1999/xlink\" width=\"100.0\" height=\"100.0\" viewBox=\"-93.75650784000001 41.91766216 0.00952668000002177 0.00411968000000229\" preserveAspectRatio=\"xMinYMin meet\"><g transform=\"matrix(1,0,0,-1,0,83.839444)\"><path fill-rule=\"evenodd\" fill=\"#66cc99\" stroke=\"#555555\" stroke-width=\"0.0001905336000004354\" opacity=\"0.6\" d=\"M -93.756155,41.918015 L -93.756155,41.921429 L -93.747334,41.921429 L -93.747334,41.918015 L -93.756155,41.918015 z\" /></g></svg>"
      ],
      "text/plain": [
       "<shapely.geometry.polygon.Polygon at 0x1ef3358f6d0>"
      ]
     },
     "execution_count": 22,
     "metadata": {},
     "output_type": "execute_result"
    }
   ],
   "source": [
    "MINX, MINY, MAXX, MAXY = [-93.756155, 41.918015, -93.747334, 41.921429]\n",
    "polygon = Polygon(((MINX, MINY), (MINX, MAXY), (MAXX, MAXY), (MAXX, MINY), (MINX, MINY)))\n",
    "polygon"
   ]
  },
  {
   "cell_type": "code",
   "execution_count": 24,
   "metadata": {},
   "outputs": [
    {
     "ename": "AttributeError",
     "evalue": "'GeoDataFrame' object has no attribute 'set_crs'",
     "output_type": "error",
     "traceback": [
      "\u001b[1;31m---------------------------------------------------------------------------\u001b[0m",
      "\u001b[1;31mAttributeError\u001b[0m                            Traceback (most recent call last)",
      "Input \u001b[1;32mIn [24]\u001b[0m, in \u001b[0;36m<cell line: 1>\u001b[1;34m()\u001b[0m\n\u001b[1;32m----> 1\u001b[0m gdf \u001b[38;5;241m=\u001b[39m \u001b[43mpl\u001b[49m\u001b[38;5;241;43m.\u001b[39;49m\u001b[43mfetch_lidar\u001b[49m\u001b[43m(\u001b[49m\u001b[43mpolygon\u001b[49m\u001b[43m,\u001b[49m\u001b[43m \u001b[49m\u001b[43m[\u001b[49m\u001b[38;5;124;43m\"\u001b[39;49m\u001b[38;5;124;43mIA_FullState\u001b[39;49m\u001b[38;5;124;43m\"\u001b[39;49m\u001b[43m]\u001b[49m\u001b[43m)\u001b[49m\n\u001b[0;32m      2\u001b[0m gdf\n",
      "File \u001b[1;32m~\\USGS_LIDAR_AgriTech\\scripts\\python_lidar.py:19\u001b[0m, in \u001b[0;36mPythonLidar.fetch_lidar\u001b[1;34m(self, polygon, regions)\u001b[0m\n\u001b[0;32m     18\u001b[0m \u001b[38;5;28;01mdef\u001b[39;00m \u001b[38;5;21mfetch_lidar\u001b[39m(\u001b[38;5;28mself\u001b[39m, polygon: Polygon, regions\u001b[38;5;241m=\u001b[39m[]):\n\u001b[1;32m---> 19\u001b[0m   \u001b[38;5;28;01mreturn\u001b[39;00m \u001b[38;5;28;43mself\u001b[39;49m\u001b[38;5;241;43m.\u001b[39;49m\u001b[43m_fetch_lidar\u001b[49m\u001b[38;5;241;43m.\u001b[39;49m\u001b[43mfetch_lidar_data\u001b[49m\u001b[43m(\u001b[49m\u001b[43mpolygon\u001b[49m\u001b[43m,\u001b[49m\u001b[43m \u001b[49m\u001b[43mregions\u001b[49m\u001b[43m)\u001b[49m\n",
      "File \u001b[1;32m~\\USGS_LIDAR_AgriTech\\scripts\\fetch_lidar.py:127\u001b[0m, in \u001b[0;36mFetchLidar.fetch_lidar_data\u001b[1;34m(self, polygon, regions)\u001b[0m\n\u001b[0;32m    116\u001b[0m \u001b[38;5;28;01mdef\u001b[39;00m \u001b[38;5;21mfetch_lidar_data\u001b[39m(\u001b[38;5;28mself\u001b[39m, polygon: Polygon, regions: \u001b[38;5;28mlist\u001b[39m) \u001b[38;5;241m-\u001b[39m\u001b[38;5;241m>\u001b[39m \u001b[38;5;28mlist\u001b[39m:\n\u001b[0;32m    117\u001b[0m   \u001b[38;5;124;03m\"\"\" Fetches lidar point cloud data from EPT resources from AWS cloud storage. \u001b[39;00m\n\u001b[0;32m    118\u001b[0m \n\u001b[0;32m    119\u001b[0m \u001b[38;5;124;03m  Args:\u001b[39;00m\n\u001b[1;32m   (...)\u001b[0m\n\u001b[0;32m    124\u001b[0m \u001b[38;5;124;03m      list: List of geopandas data frame for all regions enclosing the boundary\u001b[39;00m\n\u001b[0;32m    125\u001b[0m \u001b[38;5;124;03m  \"\"\"\u001b[39;00m\n\u001b[1;32m--> 127\u001b[0m   bound, polygon_str \u001b[38;5;241m=\u001b[39m \u001b[38;5;28;43mself\u001b[39;49m\u001b[38;5;241;43m.\u001b[39;49m\u001b[43m_gdf_helper\u001b[49m\u001b[38;5;241;43m.\u001b[39;49m\u001b[43mget_bound_from_polygon\u001b[49m\u001b[43m(\u001b[49m\u001b[43mpolygon\u001b[49m\u001b[43m)\u001b[49m\n\u001b[0;32m    128\u001b[0m   \u001b[38;5;28;01mif\u001b[39;00m \u001b[38;5;28mlen\u001b[39m(regions) \u001b[38;5;241m==\u001b[39m \u001b[38;5;241m0\u001b[39m:\n\u001b[0;32m    129\u001b[0m     regions \u001b[38;5;241m=\u001b[39m \u001b[38;5;28mself\u001b[39m\u001b[38;5;241m.\u001b[39mget_bound_metadata(bound)\n",
      "File \u001b[1;32m~\\USGS_LIDAR_AgriTech\\scripts\\gpd_helper.py:107\u001b[0m, in \u001b[0;36mGPDHelper.get_bound_from_polygon\u001b[1;34m(self, polygon)\u001b[0m\n\u001b[0;32m     98\u001b[0m \u001b[38;5;124;03m\"\"\" Computes bounds value for the given polygon\u001b[39;00m\n\u001b[0;32m     99\u001b[0m \n\u001b[0;32m    100\u001b[0m \u001b[38;5;124;03mArgs:\u001b[39;00m\n\u001b[1;32m   (...)\u001b[0m\n\u001b[0;32m    104\u001b[0m \u001b[38;5;124;03m    tuple: A tuple of Bounds object and a string of a given polygon in a form accepted by the pdal pipeline.\u001b[39;00m\n\u001b[0;32m    105\u001b[0m \u001b[38;5;124;03m\"\"\"\u001b[39;00m\n\u001b[0;32m    106\u001b[0m polygon_df \u001b[38;5;241m=\u001b[39m gpd\u001b[38;5;241m.\u001b[39mGeoDataFrame([polygon], columns\u001b[38;5;241m=\u001b[39m[\u001b[38;5;124m'\u001b[39m\u001b[38;5;124mgeometry\u001b[39m\u001b[38;5;124m'\u001b[39m])\n\u001b[1;32m--> 107\u001b[0m \u001b[43mpolygon_df\u001b[49m\u001b[38;5;241;43m.\u001b[39;49m\u001b[43mset_crs\u001b[49m(epsg\u001b[38;5;241m=\u001b[39m\u001b[38;5;28mself\u001b[39m\u001b[38;5;241m.\u001b[39moutput_epsg, inplace\u001b[38;5;241m=\u001b[39m\u001b[38;5;28;01mTrue\u001b[39;00m)\n\u001b[0;32m    108\u001b[0m polygon_df[\u001b[38;5;124m'\u001b[39m\u001b[38;5;124mgeometry\u001b[39m\u001b[38;5;124m'\u001b[39m] \u001b[38;5;241m=\u001b[39m polygon_df[\u001b[38;5;124m'\u001b[39m\u001b[38;5;124mgeometry\u001b[39m\u001b[38;5;124m'\u001b[39m]\u001b[38;5;241m.\u001b[39mto_crs(epsg\u001b[38;5;241m=\u001b[39m\u001b[38;5;28mself\u001b[39m\u001b[38;5;241m.\u001b[39minput_epsg)\n\u001b[0;32m    109\u001b[0m xmin, ymin, xmax, ymax \u001b[38;5;241m=\u001b[39m polygon_df[\u001b[38;5;124m'\u001b[39m\u001b[38;5;124mgeometry\u001b[39m\u001b[38;5;124m'\u001b[39m][\u001b[38;5;241m0\u001b[39m]\u001b[38;5;241m.\u001b[39mbounds\n",
      "File \u001b[1;32m~\\anaconda3\\lib\\site-packages\\pandas\\core\\generic.py:5575\u001b[0m, in \u001b[0;36mNDFrame.__getattr__\u001b[1;34m(self, name)\u001b[0m\n\u001b[0;32m   5568\u001b[0m \u001b[38;5;28;01mif\u001b[39;00m (\n\u001b[0;32m   5569\u001b[0m     name \u001b[38;5;129;01mnot\u001b[39;00m \u001b[38;5;129;01min\u001b[39;00m \u001b[38;5;28mself\u001b[39m\u001b[38;5;241m.\u001b[39m_internal_names_set\n\u001b[0;32m   5570\u001b[0m     \u001b[38;5;129;01mand\u001b[39;00m name \u001b[38;5;129;01mnot\u001b[39;00m \u001b[38;5;129;01min\u001b[39;00m \u001b[38;5;28mself\u001b[39m\u001b[38;5;241m.\u001b[39m_metadata\n\u001b[0;32m   5571\u001b[0m     \u001b[38;5;129;01mand\u001b[39;00m name \u001b[38;5;129;01mnot\u001b[39;00m \u001b[38;5;129;01min\u001b[39;00m \u001b[38;5;28mself\u001b[39m\u001b[38;5;241m.\u001b[39m_accessors\n\u001b[0;32m   5572\u001b[0m     \u001b[38;5;129;01mand\u001b[39;00m \u001b[38;5;28mself\u001b[39m\u001b[38;5;241m.\u001b[39m_info_axis\u001b[38;5;241m.\u001b[39m_can_hold_identifiers_and_holds_name(name)\n\u001b[0;32m   5573\u001b[0m ):\n\u001b[0;32m   5574\u001b[0m     \u001b[38;5;28;01mreturn\u001b[39;00m \u001b[38;5;28mself\u001b[39m[name]\n\u001b[1;32m-> 5575\u001b[0m \u001b[38;5;28;01mreturn\u001b[39;00m \u001b[38;5;28;43mobject\u001b[39;49m\u001b[38;5;241;43m.\u001b[39;49m\u001b[38;5;21;43m__getattribute__\u001b[39;49m\u001b[43m(\u001b[49m\u001b[38;5;28;43mself\u001b[39;49m\u001b[43m,\u001b[49m\u001b[43m \u001b[49m\u001b[43mname\u001b[49m\u001b[43m)\u001b[49m\n",
      "\u001b[1;31mAttributeError\u001b[0m: 'GeoDataFrame' object has no attribute 'set_crs'"
     ]
    }
   ],
   "source": [
    "gdf = pl.fetch_lidar(polygon, [\"IA_FullState\"])\n",
    "gdf"
   ]
  },
  {
   "cell_type": "code",
   "execution_count": 25,
   "metadata": {},
   "outputs": [
    {
     "ename": "NameError",
     "evalue": "name 'gdf' is not defined",
     "output_type": "error",
     "traceback": [
      "\u001b[1;31m---------------------------------------------------------------------------\u001b[0m",
      "\u001b[1;31mNameError\u001b[0m                                 Traceback (most recent call last)",
      "Input \u001b[1;32mIn [25]\u001b[0m, in \u001b[0;36m<cell line: 1>\u001b[1;34m()\u001b[0m\n\u001b[1;32m----> 1\u001b[0m df \u001b[38;5;241m=\u001b[39m \u001b[43mgdf\u001b[49m[\u001b[38;5;241m0\u001b[39m][\u001b[38;5;124m'\u001b[39m\u001b[38;5;124mgeo_data\u001b[39m\u001b[38;5;124m'\u001b[39m]\n",
      "\u001b[1;31mNameError\u001b[0m: name 'gdf' is not defined"
     ]
    }
   ],
   "source": [
    "df = gdf[0]['geo_data']"
   ]
  },
  {
   "cell_type": "code",
   "execution_count": 13,
   "metadata": {},
   "outputs": [
    {
     "ename": "NameError",
     "evalue": "name 'pl' is not defined",
     "output_type": "error",
     "traceback": [
      "\u001b[1;31m---------------------------------------------------------------------------\u001b[0m",
      "\u001b[1;31mNameError\u001b[0m                                 Traceback (most recent call last)",
      "Input \u001b[1;32mIn [13]\u001b[0m, in \u001b[0;36m<cell line: 1>\u001b[1;34m()\u001b[0m\n\u001b[1;32m----> 1\u001b[0m vis \u001b[38;5;241m=\u001b[39m \u001b[43mpl\u001b[49m\u001b[38;5;241m.\u001b[39mget_renderer(df)\n",
      "\u001b[1;31mNameError\u001b[0m: name 'pl' is not defined"
     ]
    }
   ],
   "source": [
    "vis = pl.get_renderer(df)"
   ]
  },
  {
   "cell_type": "code",
   "execution_count": 14,
   "metadata": {},
   "outputs": [
    {
     "ename": "NameError",
     "evalue": "name 'vis' is not defined",
     "output_type": "error",
     "traceback": [
      "\u001b[1;31m---------------------------------------------------------------------------\u001b[0m",
      "\u001b[1;31mNameError\u001b[0m                                 Traceback (most recent call last)",
      "Input \u001b[1;32mIn [14]\u001b[0m, in \u001b[0;36m<cell line: 1>\u001b[1;34m()\u001b[0m\n\u001b[1;32m----> 1\u001b[0m \u001b[43mvis\u001b[49m\u001b[38;5;241m.\u001b[39mplot_heatmap(\u001b[38;5;124m\"\u001b[39m\u001b[38;5;124mIA_FullStat\u001b[39m\u001b[38;5;124m\"\u001b[39m)\n",
      "\u001b[1;31mNameError\u001b[0m: name 'vis' is not defined"
     ]
    }
   ],
   "source": [
    "vis.plot_heatmap(\"IA_FullStat\")"
   ]
  },
  {
   "cell_type": "code",
   "execution_count": 15,
   "metadata": {},
   "outputs": [
    {
     "ename": "NameError",
     "evalue": "name 'vis' is not defined",
     "output_type": "error",
     "traceback": [
      "\u001b[1;31m---------------------------------------------------------------------------\u001b[0m",
      "\u001b[1;31mNameError\u001b[0m                                 Traceback (most recent call last)",
      "Input \u001b[1;32mIn [15]\u001b[0m, in \u001b[0;36m<cell line: 1>\u001b[1;34m()\u001b[0m\n\u001b[1;32m----> 1\u001b[0m \u001b[43mvis\u001b[49m\u001b[38;5;241m.\u001b[39mrender_3d()\n",
      "\u001b[1;31mNameError\u001b[0m: name 'vis' is not defined"
     ]
    }
   ],
   "source": [
    "vis.render_3d()"
   ]
  },
  {
   "cell_type": "code",
   "execution_count": 16,
   "metadata": {},
   "outputs": [
    {
     "data": {
      "image/svg+xml": [
       "<svg xmlns=\"http://www.w3.org/2000/svg\" xmlns:xlink=\"http://www.w3.org/1999/xlink\" width=\"100.0\" height=\"100.0\" viewBox=\"-93.75650784000001 41.91766216 0.00952668000002177 0.00411968000000229\" preserveAspectRatio=\"xMinYMin meet\"><g transform=\"matrix(1,0,0,-1,0,83.839444)\"><path fill-rule=\"evenodd\" fill=\"#66cc99\" stroke=\"#555555\" stroke-width=\"0.0001905336000004354\" opacity=\"0.6\" d=\"M -93.7517445,41.918015 L -93.756155,41.919722 L -93.7517445,41.921429 L -93.747334,41.919722 L -93.7517445,41.918015 z\" /></g></svg>"
      ],
      "text/plain": [
       "<shapely.geometry.polygon.Polygon at 0x1f939489c10>"
      ]
     },
     "execution_count": 16,
     "metadata": {},
     "output_type": "execute_result"
    }
   ],
   "source": [
    "MINX, MINY, MAXX, MAXY = [-93.756155, 41.918015, -93.747334, 41.921429]\n",
    "CENT_X = (MAXX - MINX)/2 + MINX\n",
    "CENT_Y = (MAXY - MINY)/2+MINY\n",
    "# polygon = Polygon(((MINX, MINY), (CENT_X, MAXY), (MAXX, MINY), (MINX, MINY)))\n",
    "polygon = Polygon(((CENT_X, MINY), (MINX, CENT_Y), (CENT_X, MAXY), (MAXX, CENT_Y), (CENT_X, MINY)))\n",
    "polygon"
   ]
  },
  {
   "cell_type": "code",
   "execution_count": 17,
   "metadata": {},
   "outputs": [
    {
     "ename": "NameError",
     "evalue": "name 'pl' is not defined",
     "output_type": "error",
     "traceback": [
      "\u001b[1;31m---------------------------------------------------------------------------\u001b[0m",
      "\u001b[1;31mNameError\u001b[0m                                 Traceback (most recent call last)",
      "Input \u001b[1;32mIn [17]\u001b[0m, in \u001b[0;36m<cell line: 1>\u001b[1;34m()\u001b[0m\n\u001b[1;32m----> 1\u001b[0m gdf \u001b[38;5;241m=\u001b[39m \u001b[43mpl\u001b[49m\u001b[38;5;241m.\u001b[39mfetch_lidar(polygon, [\u001b[38;5;124m\"\u001b[39m\u001b[38;5;124mIA_FullState\u001b[39m\u001b[38;5;124m\"\u001b[39m])\n\u001b[0;32m      2\u001b[0m gdf\n",
      "\u001b[1;31mNameError\u001b[0m: name 'pl' is not defined"
     ]
    }
   ],
   "source": [
    "gdf = pl.fetch_lidar(polygon, [\"IA_FullState\"])\n",
    "gdf"
   ]
  },
  {
   "cell_type": "code",
   "execution_count": 18,
   "metadata": {},
   "outputs": [
    {
     "ename": "NameError",
     "evalue": "name 'gdf' is not defined",
     "output_type": "error",
     "traceback": [
      "\u001b[1;31m---------------------------------------------------------------------------\u001b[0m",
      "\u001b[1;31mNameError\u001b[0m                                 Traceback (most recent call last)",
      "Input \u001b[1;32mIn [18]\u001b[0m, in \u001b[0;36m<cell line: 1>\u001b[1;34m()\u001b[0m\n\u001b[1;32m----> 1\u001b[0m df \u001b[38;5;241m=\u001b[39m \u001b[43mgdf\u001b[49m[\u001b[38;5;241m0\u001b[39m][\u001b[38;5;124m'\u001b[39m\u001b[38;5;124mgeo_data\u001b[39m\u001b[38;5;124m'\u001b[39m]\u001b[38;5;241m.\u001b[39mcopy()\n",
      "\u001b[1;31mNameError\u001b[0m: name 'gdf' is not defined"
     ]
    }
   ],
   "source": [
    "df = gdf[0]['geo_data'].copy()"
   ]
  },
  {
   "cell_type": "code",
   "execution_count": 19,
   "metadata": {},
   "outputs": [
    {
     "ename": "NameError",
     "evalue": "name 'pl' is not defined",
     "output_type": "error",
     "traceback": [
      "\u001b[1;31m---------------------------------------------------------------------------\u001b[0m",
      "\u001b[1;31mNameError\u001b[0m                                 Traceback (most recent call last)",
      "Input \u001b[1;32mIn [19]\u001b[0m, in \u001b[0;36m<cell line: 1>\u001b[1;34m()\u001b[0m\n\u001b[1;32m----> 1\u001b[0m vis \u001b[38;5;241m=\u001b[39m \u001b[43mpl\u001b[49m\u001b[38;5;241m.\u001b[39mget_renderer(df)\n",
      "\u001b[1;31mNameError\u001b[0m: name 'pl' is not defined"
     ]
    }
   ],
   "source": [
    "vis = pl.get_renderer(df)"
   ]
  },
  {
   "cell_type": "code",
   "execution_count": 20,
   "metadata": {},
   "outputs": [
    {
     "ename": "NameError",
     "evalue": "name 'vis' is not defined",
     "output_type": "error",
     "traceback": [
      "\u001b[1;31m---------------------------------------------------------------------------\u001b[0m",
      "\u001b[1;31mNameError\u001b[0m                                 Traceback (most recent call last)",
      "Input \u001b[1;32mIn [20]\u001b[0m, in \u001b[0;36m<cell line: 1>\u001b[1;34m()\u001b[0m\n\u001b[1;32m----> 1\u001b[0m \u001b[43mvis\u001b[49m\u001b[38;5;241m.\u001b[39mplot_heatmap(\u001b[38;5;124m\"\u001b[39m\u001b[38;5;124mIA_FullStat\u001b[39m\u001b[38;5;124m\"\u001b[39m)\n",
      "\u001b[1;31mNameError\u001b[0m: name 'vis' is not defined"
     ]
    }
   ],
   "source": [
    "vis.plot_heatmap(\"IA_FullStat\")"
   ]
  }
 ],
 "metadata": {
  "interpreter": {
   "hash": "69c0d296d865c9e09f8f8fa8b3fd65ac30d3433b287b20f31bd27b29361e3927"
  },
  "kernelspec": {
   "display_name": "Python 3 (ipykernel)",
   "language": "python",
   "name": "python3"
  },
  "language_info": {
   "codemirror_mode": {
    "name": "ipython",
    "version": 3
   },
   "file_extension": ".py",
   "mimetype": "text/x-python",
   "name": "python",
   "nbconvert_exporter": "python",
   "pygments_lexer": "ipython3",
   "version": "3.8.13"
  }
 },
 "nbformat": 4,
 "nbformat_minor": 2
}
